<robot name="F2">
  <material name="white">
    <color rgba="1 1 1 1" />
    </material>
  <material name="gray">
    <color rgba="0.75294 0.75294 0.75294 1" />
    </material>
  <mujoco>
    <compiler meshdir="./meshes" discardvisual="false" />
    </mujoco>

<!--  <link name="world"></link>-->
<!--  <joint name="floating_base_joint" type="floating">-->
<!--    <parent link="world"/>-->
<!--    <child link="pelvis"/>-->
<!--  </joint>-->

  <link name="pelvis">
    <inertial>
      <origin xyz="0.00001227 0 0.00175202" rpy="0 0 0" />
      <mass value="1.923" />
      <inertia ixx="0.00328639" ixy="-0.00000755" ixz="0.00000009" iyy="0.00187879" iyz="0.00000004" izz="0.00327877" />
    </inertial>
    <visual>
      <geometry>
        <mesh filename="meshes/pelvis.STL" />
        </geometry>
      <material name="gray" />
    </visual>
    <collision>
      <geometry>
        <mesh filename="meshes/pelvis.STL" />
        </geometry>
    </collision>
 </link>
 <link name="left_hip_pitch_link">
    <inertial>
      <origin xyz="-0.00059823 0.05397898 -0.0042224" rpy="0 0 0" />
      <mass value="1.04" />
      <inertia ixx="0.00138498" ixy="-0.00001433" ixz="0.00000848" iyy="0.00087841" iyz="-0.00003918" izz="0.00113076" />
    </inertial>
    <visual>
      <origin xyz="0 0 0" rpy="0 0 0" />
      <geometry>
        <mesh filename="meshes/left_hip_pitch_link.STL" />
      </geometry>
      <material name="">
        <color rgba="0.75294 0.75294 0.75294 1" />
      </material>
    </visual>
<!--    <collision>-->
<!--      <origin xyz="0 0 0" rpy="0 0 0" />-->
<!--      <geometry>-->
<!--        <mesh filename="meshes/left_hip_pitch_link.STL" />-->
<!--      </geometry>-->
<!--    </collision>-->
  </link>
  <joint name="left_hip_pitch_joint" type="revolute">
    <origin xyz="0 0.0495 0" rpy="0 0 0" />
    <parent link="pelvis" />
    <child link="left_hip_pitch_link" />
    <axis xyz="0 1 0" />
    <limit lower="-2.3562" upper="2.3562" effort="75" velocity="6.28" />
  </joint>
   <link name="left_hip_roll_link">
    <inertial>
      <origin xyz="0.0043213 0 -0.027634" rpy="0 0 0" />
      <mass value="0.14" />
      <inertia ixx="0.0001063" ixy="3E-08" ixz="1.232E-05" iyy="0.00018358" iyz="0" izz="0.0001369" />
    </inertial>
    <visual>
      <origin xyz="0 0 0" rpy="0 0 0" />
      <geometry>
        <mesh filename="meshes/left_hip_roll_link.STL" />
      </geometry>
      <material name="">
        <color rgba="0.75294 0.75294 0.75294 1" />
      </material>
    </visual>
<!--    <collision>-->
<!--      <origin xyz="0 0 0" rpy="0 0 0" />-->
<!--      <geometry>-->
<!--        <mesh filename="meshes/left_hip_roll_link.STL" />-->
<!--      </geometry>-->
<!--    </collision>-->
  </link>
  <joint name="left_hip_roll_joint" type="revolute">
    <origin xyz="0 0.0555 -0.005" rpy="0 0 0" />
    <parent link="left_hip_pitch_link" />
    <child link="left_hip_roll_link" />
    <axis xyz="1 0 0" />
    <limit lower="-0.5236" upper="1.5708" effort="87" velocity="5.44" />
  </joint>
  <link name="left_hip_yaw_link">
    <inertial>
      <origin xyz="0.00010121 1.383E-05 -0.10231138" rpy="0 0 0" />
      <mass value="2.275" />
      <inertia ixx="0.01919661" ixy="1.19E-06" ixz="-8.643E-05" iyy="0.01865712" iyz="0.0001231" izz="0.00224849" />
    </inertial>
    <visual>
      <origin xyz="0 0 0" rpy="0 0 0" />
      <geometry>
        <mesh filename="meshes/left_hip_yaw_link.STL" />
      </geometry>
      <material name="">
        <color rgba="0.75294 0.75294 0.75294 1" />
      </material>
    </visual>
<!--    <collision>-->
<!--      <origin xyz="0 0 0" rpy="0 0 0" />-->
<!--      <geometry>-->
<!--        <mesh filename="meshes/left_hip_yaw_link.STL" />-->
<!--      </geometry>-->
<!--    </collision>-->
  </link>
  <joint name="left_hip_yaw_joint" type="revolute">
    <origin xyz="0 0 -0.0536" rpy="0 0 0" />
    <parent link="left_hip_roll_link" />
    <child link="left_hip_yaw_link" />
    <axis xyz="0 0 1" />
    <limit lower="-1.8326" upper="1.8326" effort="87" velocity="5.44" />
  </joint>
  <link name="left_knee_link">
    <inertial>
      <origin xyz="0.00334882 -0.00032247 -0.14984229" rpy="0 0 0" />
      <mass value="0.635" />
      <inertia ixx="0.01100766" ixy="-8.8E-07" ixz="0.00025894" iyy="0.01110149" iyz="-5.385E-05" izz="0.00031791" />
    </inertial>
    <visual>
      <origin xyz="0 0 0" rpy="0 0 0" />
      <geometry>
        <mesh filename="meshes/left_knee_link.STL" />
      </geometry>
      <material name="">
        <color rgba="0.75294 0.75294 0.75294 1" />
      </material>
    </visual>
<!--    <collision>-->
<!--      <origin xyz="0 0 0" rpy="0 0 0" />-->
<!--      <geometry>-->
<!--        <mesh filename="meshes/left_knee_link.STL" />-->
<!--      </geometry>-->
<!--    </collision>-->
  </link>
  <joint name="left_knee_joint" type="revolute">
    <origin xyz="0 0 -0.3304" rpy="0 0 0" />
    <parent link="left_hip_yaw_link" />
    <child link="left_knee_link" />
    <axis xyz="0 1 0" />
    <limit lower="-0.01745" upper="2.3562" effort="120" velocity="12.56" />
  </joint>
  <link name="left_ankle_pitch_link">
    <inertial>
      <origin xyz="0.0024178 -1.256E-05 -0.02381757" rpy="0 0 0" />
      <mass value="0.22" />
      <inertia ixx="0.00016894" ixy="-4E-08" ixz="-1.04E-05" iyy="0.00023561" iyz="2E-08" izz="0.00010149" />
    </inertial>
    <visual>
      <origin xyz="0 0 0" rpy="0 0 0" />
      <geometry>
        <mesh filename="meshes/left_ankle_pitch_link.STL" />
      </geometry>
      <material name="">
        <color rgba="0.75294 0.75294 0.75294 1" />
      </material>
    </visual>
<!--    <collision>-->
<!--      <origin xyz="0 0 0" rpy="0 0 0" />-->
<!--      <geometry>-->
<!--        <mesh filename="meshes/left_ankle_pitch_link.STL" />-->
<!--      </geometry>-->
<!--    </collision>-->
  </link>
  <joint name="left_ankle_pitch_joint" type="revolute">
    <origin xyz="0 0 -0.39" rpy="0 0 0" />
    <parent link="left_knee_link" />
    <child link="left_ankle_pitch_link" />
    <axis xyz="0 1 0" />
    <limit lower="-0.873" upper="1.0472" effort="89" velocity="17.8" />
  </joint>
  <link name="left_ankle_roll_link">
    <inertial>
      <origin xyz="0.05108755 0.00023922 -0.00447269" rpy="0 0 0" />
      <mass value="0.411" />
<!--      <inertia ixx="9.993E-05" ixy="0" ixz="0" iyy="0.00047226" iyz="0" izz="0.00047916" />-->
      <inertia ixx="0.01" ixy="0" ixz="0" iyy="0.01" iyz="0" izz="0.01" />
    </inertial>
    <visual>
      <origin xyz="0 0 0" rpy="0 0 0" />
      <geometry>
        <mesh filename="meshes/left_ankle_roll_link.STL" />
      </geometry>
      <material name="">
        <color rgba="0.75294 0.75294 0.75294 1" />
      </material>
    </visual>
<!--    <collision><origin xyz=" 0.040   0.000  -0.013"/><geometry><box size="0.21 0.066 0.02"/></geometry></collision>-->
<!--    <collision><origin xyz="0.042  0.000 -0.030" rpy="0 1.570796 0"/><geometry><capsule radius="0.006" length="0.240"/></geometry></collision>   &lt;!&ndash;capsule  cylinder&ndash;&gt;-->
<!--    <collision><origin xyz="0.043  0.035 -0.030" rpy="0 1.570796 0"/><geometry><capsule radius="0.006" length="0.205"/></geometry></collision>-->
<!--    <collision><origin xyz="0.043 -0.035 -0.030" rpy="0 1.570796 0"/><geometry><capsule radius="0.006" length="0.205"/></geometry></collision>-->

    <collision><origin xyz=" 0.040   0.000  -0.013"/><geometry><box size="0.21 0.066 0.02"/></geometry></collision>
    <collision><origin xyz="-0.066   0.034  -0.030"/><geometry><sphere radius="0.006"/></geometry></collision>
    <collision><origin xyz="-0.066  -0.034  -0.030"/><geometry><sphere radius="0.006"/></geometry></collision>
    <collision><origin xyz=" 0.150   0.036  -0.030"/><geometry><sphere radius="0.006"/></geometry></collision>
    <collision><origin xyz=" 0.150  -0.036  -0.030"/><geometry><sphere radius="0.006"/></geometry></collision>
  </link>
  <joint name="left_ankle_roll_joint" type="revolute">
    <origin xyz="0 0 -0.058" rpy="0 0 0" />
    <parent link="left_ankle_pitch_link" />
    <child link="left_ankle_roll_link" />
    <axis xyz="1 0 0" />
    <limit lower="-0.5236" upper="0.5236" effort="12" velocity="4.19" />
  </joint>
  <link name="right_hip_pitch_link">
    <inertial>
      <origin xyz="-0.00059823 -0.05397898 -0.0042224" rpy="0 0 0" />
      <mass value="1.04" />
      <inertia ixx="0.00138498" ixy="0.00001433" ixz="0.00000848" iyy="0.00087841" iyz="0.00003918" izz="0.00113076" />
    </inertial>
    <visual>
      <origin xyz="0 0 0" rpy="0 0 0" />
      <geometry>
        <mesh filename="meshes/right_hip_pitch_link.STL" />
      </geometry>
      <material name="">
        <color rgba="0.75294 0.75294 0.75294 1" />
      </material>
    </visual>
<!--    <collision>-->
<!--      <origin xyz="0 0 0" rpy="0 0 0" />-->
<!--      <geometry>-->
<!--        <mesh filename="meshes/right_hip_pitch_link.STL" />-->
<!--      </geometry>-->
<!--    </collision>-->
  </link>
  <joint name="right_hip_pitch_joint" type="revolute">
    <origin xyz="0 -0.0495 0" rpy="0 0 0" />
    <parent link="pelvis" />
    <child link="right_hip_pitch_link" />
    <axis xyz="0 1 0" />
    <limit lower="-2.3562" upper="2.3562" effort="75" velocity="6.28" />
  </joint>
 <link name="right_hip_roll_link">
    <inertial>
      <origin xyz="0.0043213 0 -0.027634" rpy="0 0 0" />
      <mass value="0.14" />
      <inertia ixx="0.0001063" ixy="3E-08" ixz="1.232E-05" iyy="0.00018358" iyz="0" izz="0.0001369" />
    </inertial>
    <visual>
      <origin xyz="0 0 0" rpy="0 0 0" />
      <geometry>
        <mesh filename="meshes/right_hip_roll_link.STL" />
      </geometry>
      <material name="">
        <color rgba="0.75294 0.75294 0.75294 1" />
      </material>
    </visual>
<!--    <collision>-->
<!--      <origin xyz="0 0 0" rpy="0 0 0" />-->
<!--      <geometry>-->
<!--        <mesh filename="meshes/right_hip_roll_link.STL" />-->
<!--      </geometry>-->
<!--    </collision>-->
  </link>
  <joint name="right_hip_roll_joint" type="revolute">
    <origin xyz="0 -0.0555 -0.005" rpy="0 0 0" />
    <parent link="right_hip_pitch_link" />
    <child link="right_hip_roll_link" />
    <axis xyz="1 0 0" />
    <limit lower="-1.5708" upper="0.5236" effort="87" velocity="5.44" />
  </joint>
  <link name="right_hip_yaw_link">
    <inertial>
      <origin xyz="0.00028095 -0.00037298 -0.10231138" rpy="0 0 0" />
      <mass value="2.275" />
      <inertia ixx="0.019196" ixy="1.44E-06" ixz="-4.552E-05" iyy="0.018657" iyz="5.099E-05" izz="0.002248" />
    </inertial>
    <visual>
      <origin xyz="0 0 0" rpy="0 0 0" />
      <geometry>
        <mesh filename="meshes/right_hip_yaw_link.STL" />
      </geometry>
      <material name="">
        <color rgba="0.75294 0.75294 0.75294 1" />
      </material>
    </visual>
<!--    <collision>-->
<!--      <origin xyz="0 0 0" rpy="0 0 0" />-->
<!--      <geometry>-->
<!--        <mesh filename="meshes/right_hip_yaw_link.STL" />-->
<!--      </geometry>-->
<!--    </collision>-->
  </link>
  <joint name="right_hip_yaw_joint" type="revolute">
    <origin xyz="0 0 -0.0536" rpy="0 0 0" />
    <parent link="right_hip_roll_link" />
    <child link="right_hip_yaw_link" />
    <axis xyz="0 0 1" />
    <limit lower="-1.8326" upper="1.8326" effort="87" velocity="5.44" />
  </joint>
  <link name="right_knee_link">
    <inertial>
      <origin xyz="0.0033489 -0.00032248 -0.14984" rpy="0 0 0" />
      <mass value="0.635" />
      <inertia ixx="0.011008" ixy="8.8E-07" ixz="0.00025894" iyy="0.011101" iyz="5.385E-05" izz="0.00031791" />
    </inertial>
    <visual>
      <origin xyz="0 0 0" rpy="0 0 0" />
      <geometry>
        <mesh filename="meshes/right_knee_link.STL" />
      </geometry>
      <material name="">
        <color rgba="0.75294 0.75294 0.75294 1" />
      </material>
    </visual>
<!--    <collision>-->
<!--      <origin xyz="0 0 0" rpy="0 0 0" />-->
<!--      <geometry>-->
<!--        <mesh filename="meshes/right_knee_link.STL" />-->
<!--      </geometry>-->
<!--    </collision>-->
  </link>
  <joint name="right_knee_joint" type="revolute">
    <origin xyz="0 0 -0.3304" rpy="0 0 0" />
    <parent link="right_hip_yaw_link" />
    <child link="right_knee_link" />
    <axis xyz="0 1 0" />
    <limit lower="-0.01745" upper="2.3562" effort="120" velocity="12.56" />
  </joint>
  <link name="right_ankle_pitch_link">
    <inertial>
      <origin xyz="0.0024178 -1.257E-05 -0.023818" rpy="0 0 0" />
      <mass value="0.22" />
      <inertia ixx="0.00016894" ixy="-4E-08" ixz="-1.04E-05" iyy="0.00023561" iyz="2E-08" izz="0.00010149" />
    </inertial>
    <visual>
      <origin xyz="0 0 0" rpy="0 0 0" />
      <geometry>
        <mesh filename="meshes/right_ankle_pitch_link.STL" />
      </geometry>
      <material name="">
        <color rgba="0.75294 0.75294 0.75294 1" />
      </material>
    </visual>
<!--    <collision>-->
<!--      <origin xyz="0 0 0" rpy="0 0 0" />-->
<!--      <geometry>-->
<!--        <mesh filename="meshes/right_ankle_pitch_link.STL" />-->
<!--      </geometry>-->
<!--    </collision>-->
  </link>
  <joint name="right_ankle_pitch_joint" type="revolute">
    <origin xyz="0 0 -0.39" rpy="0 0 0" />
    <parent link="right_knee_link" />
    <child link="right_ankle_pitch_link" />
    <axis xyz="0 1 0" />
    <limit lower="-0.873" upper="1.0472" effort="89" velocity="17.8" />
  </joint>
  <link name="right_ankle_roll_link">
    <inertial>
      <origin xyz="0.05108756 0.00023921 -0.00447269" rpy="0 0 0" />
      <mass value="0.411" />
<!--      <inertia ixx="9.993E-05" ixy="0" ixz="0" iyy="0.00047226" iyz="0" izz="0.00047916" />-->
      <inertia ixx="0.01" ixy="0" ixz="0" iyy="0.01" iyz="0" izz="0.01" />
    </inertial>
    <visual>
      <origin xyz="0 0 0" rpy="0 0 0" />
      <geometry>
        <mesh filename="meshes/right_ankle_roll_link.STL" />
      </geometry>
      <material name="">
        <color rgba="0.75294 0.75294 0.75294 1" />
      </material>
    </visual>
<!--    <collision><origin xyz=" 0.040   0.000  -0.013"/><geometry><box size="0.21 0.066 0.02"/></geometry></collision>-->
<!--    <collision><origin xyz="0.042  0.000 -0.030" rpy="0 1.570796 0"/><geometry><capsule radius="0.006" length="0.240"/></geometry></collision>   &lt;!&ndash;capsule  cylinder&ndash;&gt;-->
<!--    <collision><origin xyz="0.043  0.035 -0.030" rpy="0 1.570796 0"/><geometry><capsule radius="0.006" length="0.205"/></geometry></collision>-->
<!--    <collision><origin xyz="0.043 -0.035 -0.030" rpy="0 1.570796 0"/><geometry><capsule radius="0.006" length="0.205"/></geometry></collision>-->

    <collision><origin xyz=" 0.040   0.000  -0.013"/><geometry><box size="0.21 0.066 0.02"/></geometry></collision>
    <collision><origin xyz="-0.066   0.034  -0.030"/><geometry><sphere radius="0.006"/></geometry></collision>
    <collision><origin xyz="-0.066  -0.034  -0.030"/><geometry><sphere radius="0.006"/></geometry></collision>
    <collision><origin xyz=" 0.150   0.036  -0.030"/><geometry><sphere radius="0.006"/></geometry></collision>
    <collision><origin xyz=" 0.150  -0.036  -0.030"/><geometry><sphere radius="0.006"/></geometry></collision>
  </link>
  <joint name="right_ankle_roll_joint" type="revolute">
    <origin xyz="0 0 -0.058" rpy="0 0 0" />
    <parent link="right_ankle_pitch_link" />
    <child link="right_ankle_roll_link" />
    <axis xyz="1 0 0" />
    <limit lower="-0.5236" upper="0.5236" effort="12" velocity="4.19" />
  </joint>
   <link name="waist_yaw_link">
    <inertial>
      <origin xyz="0 0 -0.038" rpy="0 0 0" />
      <mass value="0.015" />
      <inertia ixx="2.0041E-06" ixy="9.0151E-24" ixz="7.3908E-21" iyy="2.0041E-06" iyz="-5.9729E-21" izz="3.7638E-06" />
    </inertial>
    <visual>
      <origin xyz="0 0 0" rpy="0 0 0" />
      <geometry>
        <mesh filename="meshes/waist_yaw_link.STL" />
      </geometry>
      <material name="">
        <color rgba="1 1 1 1" />
      </material>
    </visual>
  </link>
  <joint name="waist_yaw_joint" type="revolute">
    <origin xyz="0 0 0.0955" rpy="0 0 0" />
    <parent link="pelvis" />
    <child link="waist_yaw_link" />
    <axis xyz="0 0 1" />
    <limit lower="-1.5708" upper="1.5708" effort="87" velocity="5.44" />
  </joint>
  <link name="waist_roll_link">
    <inertial>
      <origin xyz="-0.00017849 0 0.00743447" rpy="0 0 0" />
      <mass value="0.259" />
      <inertia ixx="0.00008431" ixy="0" ixz="-0.00000123" iyy="0.00011059" iyz="0" izz="0.00010442" />
    </inertial>
    <visual>
      <origin xyz="0 0 0" rpy="0 0 0" />
      <geometry>
        <mesh filename="meshes/waist_roll_link.STL" />
      </geometry>
      <material name="">
        <color rgba="1 1 1 1" />
      </material>
    </visual>
<!--    <collision>-->
<!--      <origin xyz="0 0 0" rpy="0 0 0" />-->
<!--      <geometry>-->
<!--        <mesh filename="meshes/waist_roll_link.STL" />-->
<!--      </geometry>-->
<!--    </collision>-->
  </link>
  <joint name="waist_roll_fixed" type="fixed">
    <origin xyz="0 0 0" rpy="0 0 0" />
    <parent link="waist_yaw_link" />
    <child link="waist_roll_link" />
    <axis xyz="1 0 0" />
    <limit lower="-0.5236" upper="0.5236" effort="87" velocity="5.44" />
  </joint>
  <link name="torso_link">
    <inertial>
      <origin xyz="-0.00019931 0.00150681 0.18511433" rpy="0 0 0" />
      <mass value="7.609" />
      <inertia ixx="0.12117891" ixy="0" ixz="0" iyy="0.12019937" iyz="0" izz="0.02185198" />
    </inertial>
    <visual>
      <origin xyz="0 0 0" rpy="0 0 0" />
      <geometry>
        <mesh filename="meshes/torso_link.STL" />
      </geometry>
      <material name="">
        <color rgba="0.5 0 0 1" />
      </material>
    </visual>
<!--    <collision>-->
<!--      <origin xyz="0 0 0" rpy="0 0 0" />-->
<!--      <geometry>-->
<!--        <mesh filename="meshes/torso_link.STL" />-->
<!--      </geometry>-->
<!--    </collision>-->
  </link>
  <joint name="waist_roll_joint" type="revolute">
    <origin xyz="0 0 0" rpy="0 0 0" />
    <parent link="waist_yaw_link" />
    <child link="torso_link" />
    <axis xyz="1 0 0" />
    <limit lower="-0.5236" upper="0.5236" effort="87" velocity="5.44" />
  </joint>
  <link name="left_shoulder_pitch_link">
    <inertial>
      <origin xyz="0.00005543 0.05545328 0.00005429" rpy="0 0 0" />
      <mass value="1.277" />
      <inertia ixx="0.00178135" ixy="-0.00000046" ixz="-0.00000005" iyy="0.00103975" iyz="0.00000145" izz="0.00194002" />
    </inertial>
    <visual>
      <geometry>
        <mesh filename="meshes/left_shoulder_pitch_link.STL" />
        </geometry>
      <material name="gray" />
    </visual>
<!--    <collision>-->
<!--      <geometry>-->
<!--        <mesh filename="meshes/left_shoulder_pitch_link.STL" />-->
<!--        </geometry>-->
<!--    </collision>-->
  </link>
  <joint name="left_shoulder_pitch_joint" type="fixed">
    <origin xyz="-0.015 0.05635 0.342" rpy="0 0 0" />
    <parent link="torso_link" />
    <child link="left_shoulder_pitch_link" />
    <axis xyz="0 1 0" />
    <limit lower="-3.6652" upper="2.0944" effort="48" velocity="6.28" />
    </joint>
  <link name="left_shoulder_roll_link">
    <inertial>
      <origin xyz="0.00000000 -0.00015563 -0.00797243" rpy="0 0 0" />
      <mass value="0.229" />
      <inertia ixx="0.00005784" ixy="0.00000000" ixz="0.00000000" iyy="0.00007040" iyz="0.00000085" izz="0.00006618" />
      </inertial>
    <visual>
      <geometry>
        <mesh filename="meshes/left_shoulder_roll_link.STL" />
        </geometry>
      <material name="gray" />
      </visual>
<!--    <collision>-->
<!--      <geometry>-->
<!--        <mesh filename="meshes/left_shoulder_roll_link.STL" />-->
<!--        </geometry>-->
<!--      </collision>-->
    </link>
  <joint name="left_shoulder_roll_joint" type="fixed">
    <origin xyz="0 0.1031 0" rpy="0 0 0" />
    <parent link="left_shoulder_pitch_link" />
    <child link="left_shoulder_roll_link" />
    <axis xyz="1 0 0" />
    <limit lower="-0.2618" upper="2.356" effort="84" velocity="6.07" />
    </joint>
  <link name="left_shoulder_yaw_link">
    <inertial>
      <origin xyz="-0.000078318 0.0010110 -0.12915032" rpy="0 0 0" />
      <mass value="1.194" />
      <inertia ixx="0.00412845" ixy="0" ixz="0" iyy="0.00411827" iyz="0" izz="0.00084103" />
      </inertial>
    <visual>
      <geometry>
        <mesh filename="meshes/left_shoulder_yaw_link.STL" />
        </geometry>
      <material name="gray" />
      </visual>
<!--    <collision>-->
<!--      <geometry>-->
<!--        <mesh filename="meshes/left_shoulder_yaw_link.STL" />-->
<!--        </geometry>-->
<!--      </collision>-->
    </link>
  <joint name="left_shoulder_yaw_joint" type="fixed">
    <origin xyz="0 0 0" rpy="0 0 0" />
    <parent link="left_shoulder_roll_link" />
    <child link="left_shoulder_yaw_link" />
    <axis xyz="0 0 1" />
    <limit lower="-2.1817" upper="2.1817" effort="84" velocity="6.07" />
    </joint>
  <link name="left_elbow_link">
    <inertial>
      <origin xyz="0.01677410 0.00000000 -0.00133301" rpy="0 0 0" />
      <mass value="0.185" />
      <inertia ixx="0.00007998" ixy="0.00000000" ixz="-0.00000281" iyy="0.00011358" iyz="0.00000000" izz="0.00012455" />
      </inertial>
    <visual>
      <geometry>
        <mesh filename="meshes/left_elbow_link.STL" />
        </geometry>
      <material name="gray" />
      </visual>
<!--    <collision>-->
<!--      <geometry>-->
<!--        <mesh filename="meshes/left_elbow_link.STL" />-->
<!--        </geometry>-->
<!--      </collision>-->
    </link>
  <joint name="left_elbow_joint" type="fixed">
    <origin xyz="0 0 -0.2295" rpy="0 0 0" />
    <parent link="left_shoulder_yaw_link" />
    <child link="left_elbow_link" />
    <axis xyz="0 1 0" />
    <limit lower="-0.6981" upper="1.5707" effort="37" velocity="7.33" />
    </joint>
  <link name="left_wrist_roll_link">
    <inertial>
      <origin xyz="0.09853864 -0.00025438 -0.00071846" rpy="0 0 0" />
      <mass value="1.372" />
      <inertia ixx="0.00048823" ixy="-0.00004194" ixz="0.00006322" iyy="0.00443117" iyz="-0.00000048" izz="0.00434552" />
      </inertial>
    <visual>
      <geometry>
        <mesh filename="meshes/left_wrist_roll_link.STL" />
        </geometry>
      <material name="gray" />
      </visual>
<!--    <collision>-->
<!--      <geometry>-->
<!--        <mesh filename="meshes/left_wrist_roll_link.STL" />-->
<!--        </geometry>-->
<!--      </collision>-->
    </link>
  <joint name="left_wrist_roll_joint" type="fixed">
    <origin xyz="0 0 0" rpy="0 0 0" />
    <parent link="left_elbow_link" />
    <child link="left_wrist_roll_link" />
    <axis xyz="1 0 0" />
    <limit lower="-2.0071" upper="2.0071" effort="37" velocity="7.33" />
    </joint>
  <link name="left_wrist_pitch_link">
    <inertial>
      <origin xyz="0.0075268 0 0" rpy="0 0 0" />
      <mass value="0.042" />
      <inertia ixx="0.00001052" ixy="0" ixz="0" iyy="0.00000783" iyz="0" izz="0.00001443" />
      </inertial>
    <visual>
      <geometry>
        <mesh filename="meshes/left_wrist_pitch_link.STL" />
        </geometry>
      <material name="gray" />
      </visual>
<!--    <collision>-->
<!--      <geometry>-->
<!--        <mesh filename="meshes/left_wrist_pitch_link.STL" />-->
<!--        </geometry>-->
<!--      </collision>-->
    </link>
  <joint name="left_wrist_pitch_joint" type="fixed">
    <origin xyz="0.23 0 0" rpy="0 0 0" />
    <parent link="left_wrist_roll_link" />
    <child link="left_wrist_pitch_link" />
    <axis xyz="0 1 0" />
    <limit lower="-0.5236" upper="0.5236" effort="20" velocity="6.28" />
    </joint>
  <link name="left_wrist_yaw_link">
    <inertial>
      <origin xyz="0.01214655 -0.00027873 -0.00050944" rpy="0 0 0" />
      <mass value="0.12" />
      <inertia ixx="0.00004229" ixy="-0.00000030" ixz="0.00000111" iyy="0.00006089" iyz="-0.00000016" izz="0.00005074" />
      </inertial>
    <visual>
      <geometry>
        <mesh filename="meshes/left_wrist_yaw_link.STL" />
        </geometry>
      <material name="gray" />
      </visual>
    </link>
  <joint name="left_wrist_yaw_joint" type="fixed">
    <origin xyz="0.021 0 0" rpy="0 0 0" />
    <parent link="left_wrist_pitch_link" />
    <child link="left_wrist_yaw_link" />
    <axis xyz="0 0 1" />
    <limit lower="-1.1344" upper="1.1344" effort="25" velocity="4.44" />
    </joint>
  <link name="left_hand_link">
    <inertial>
      <origin xyz="0.07685741 -0.00813146 0.00998713" rpy="0 0 0" />
      <mass value="0.41" />
      <inertia ixx="0.00046572" ixy="6.572E-05" ixz="-0.00011163" iyy="0.00115798" iyz="-0.00014439" izz="0.0010193" />
      </inertial>
    <visual>
      <geometry>
        <mesh filename="meshes/left_hand_link.STL" />
        </geometry>
      <material name="white" />
      </visual>
<!--    <collision>-->
<!--      <geometry>-->
<!--        <mesh filename="meshes/left_hand_link.STL" />-->
<!--        </geometry>-->
<!--      </collision>-->
    </link>
  <joint name="left_hand_joint" type="fixed">
    <origin xyz="0.031 0 0" rpy="0 0 0" />
    <parent link="left_wrist_yaw_link" />
    <child link="left_hand_link" />
  </joint>
  <link name="right_shoulder_pitch_link">
    <inertial>
      <origin xyz="0.00015543 -0.05545328 -0.00005429" rpy="0 0 0" />
      <mass value="1.277" />
      <inertia ixx="0.00178135" ixy="0.00000046" ixz="0.00000005" iyy="0.00103975" iyz="0.00000145" izz="0.00194002" />
      </inertial>
    <visual>
      <geometry>
        <mesh filename="meshes/right_shoulder_pitch_link.STL" />
        </geometry>
      <material name="gray" />
      </visual>
<!--    <collision>-->
<!--      <geometry>-->
<!--        <mesh filename="meshes/right_shoulder_pitch_link.STL" />-->
<!--        </geometry>-->
<!--      </collision>-->
    </link>
  <joint name="right_shoulder_pitch_joint" type="fixed">
    <origin xyz="-0.015 -0.05635 0.342" rpy="0 0 0" />
    <parent link="torso_link" />
    <child link="right_shoulder_pitch_link" />
    <axis xyz="0 1 0" />
    <limit lower="-3.6652" upper="2.0944" effort="48" velocity="6.28" />
  </joint>
  <link name="right_shoulder_roll_link">
    <inertial>
      <origin xyz="0.00000000 -0.00015563 -0.00797243" rpy="0 0 0" />
      <mass value="0.229" />
      <inertia ixx="0.00005784" ixy="0.00000000" ixz="0.00000000" iyy="0.00007040" iyz="0.00000085" izz="0.00006618" />
      </inertial>
    <visual>
      <geometry>
        <mesh filename="meshes/right_shoulder_roll_link.STL" />
        </geometry>
      <material name="gray" />
      </visual>
<!--    <collision>-->
<!--      <geometry>-->
<!--        <mesh filename="meshes/right_shoulder_roll_link.STL" />-->
<!--        </geometry>-->
<!--      </collision>-->
    </link>
  <joint name="right_shoulder_roll_joint" type="fixed">
    <origin xyz="0 -0.1031 0" rpy="0 0 0" />
    <parent link="right_shoulder_pitch_link" />
    <child link="right_shoulder_roll_link" />
    <axis xyz="1 0 0" />
    <limit lower="-2.356" upper="0.2618" effort="84" velocity="6.07" />
    </joint>
  <link name="right_shoulder_yaw_link">
    <inertial>
      <origin xyz="-0.000078318 0.0010110 -0.12915032" rpy="0 0 0" />
      <mass value="1.194" />
      <inertia ixx="0.00412845" ixy="0" ixz="0" iyy="0.00411827" iyz="0" izz="0.00084103" />
      </inertial>
    <visual>
      <geometry>
        <mesh filename="meshes/right_shoulder_yaw_link.STL" />
        </geometry>
      <material name="gray" />
      </visual>
<!--    <collision>-->
<!--      <geometry>-->
<!--        <mesh filename="meshes/right_shoulder_yaw_link.STL" />-->
<!--        </geometry>-->
<!--      </collision>-->
    </link>
  <joint name="right_shoulder_yaw_joint" type="fixed">
    <origin xyz="0 0 0" rpy="0 0 0" />
    <parent link="right_shoulder_roll_link" />
    <child link="right_shoulder_yaw_link" />
    <axis xyz="0 0 1" />
    <limit lower="-2.1817" upper="2.1817" effort="84" velocity="6.07" />
    </joint>
  <link name="right_elbow_link">
    <inertial>
      <origin xyz="0.01677410 0.00000000 -0.00133301" rpy="0 0 0" />
      <mass value="0.185" />
      <inertia ixx="0.00007998" ixy="0.00000000" ixz="-0.00000281" iyy="0.00011358" iyz="0.00000000" izz="0.00012455" />
      </inertial>
    <visual>
      <geometry>
        <mesh filename="meshes/right_elbow_link.STL" />
        </geometry>
      <material name="gray" />
      </visual>
<!--    <collision>-->
<!--      <geometry>-->
<!--        <mesh filename="meshes/right_elbow_link.STL" />-->
<!--        </geometry>-->
<!--      </collision>-->
    </link>
  <joint name="right_elbow_joint" type="fixed">
    <origin xyz="0 0 -0.2295" rpy="0 0 0" />
    <parent link="right_shoulder_yaw_link" />
    <child link="right_elbow_link" />
    <axis xyz="0 1 0" />
    <limit lower="-0.6981" upper="1.5707" effort="37" velocity="7.33" />
    </joint>
  <link name="right_wrist_roll_link">
    <inertial>
      <origin xyz="0.09853864 -0.00025438 -0.00071846" rpy="0 0 0" />
      <mass value="1.372" />
      <inertia ixx="0.00048823" ixy="-0.00004194" ixz="0.00006322" iyy="0.00443117" iyz="-0.00000048" izz="0.00434552" />
      </inertial>
    <visual>
      <geometry>
        <mesh filename="meshes/right_wrist_roll_link.STL" />
        </geometry>
      <material name="gray" />
      </visual>
<!--    <collision>-->
<!--      <geometry>-->
<!--        <mesh filename="meshes/right_wrist_roll_link.STL" />-->
<!--        </geometry>-->
<!--      </collision>-->
    </link>
  <joint name="right_wrist_roll_joint" type="fixed">
    <origin xyz="0 0 0" rpy="0 0 0" />
    <parent link="right_elbow_link" />
    <child link="right_wrist_roll_link" />
    <axis xyz="1 0 0" />
    <limit lower="-2.0071" upper="2.0071" effort="37" velocity="7.33" />
    </joint>
  <link name="right_wrist_pitch_link">
    <inertial>
      <origin xyz="0.0075268 0.00000000 0.00000000" rpy="0 0 0" />
      <mass value="0.042" />
      <inertia ixx="0.00001052" ixy="0.00000000" ixz="0.00000000" iyy="0.00000783" iyz="0.00000000" izz="0.00001443" />
      </inertial>
    <visual>
      <geometry>
        <mesh filename="meshes/right_wrist_pitch_link.STL" />
        </geometry>
      <material name="gray" />
      </visual>
<!--    <collision>-->
<!--      <geometry>-->
<!--        <mesh filename="meshes/right_wrist_pitch_link.STL" />-->
<!--        </geometry>-->
<!--      </collision>-->
    </link>
  <joint name="right_wrist_pitch_joint" type="fixed">
    <origin xyz="0.23 0 0" rpy="0 0 0" />
    <parent link="right_wrist_roll_link" />
    <child link="right_wrist_pitch_link" />
    <axis xyz="0 1 0" />
    <limit lower="-0.5236" upper="0.5236" effort="20" velocity="6.28" />
    </joint>
  <link name="right_wrist_yaw_link">
    <inertial>
      <origin xyz="0.01214655 -0.00027873 -0.00050944" rpy="0 0 0" />
      <mass value="0.12" />
      <inertia ixx="0.00004229" ixy="-0.00000030" ixz="0.00000111" iyy="0.00006089" iyz="-0.00000016" izz="0.00005074" />
      </inertial>
    <visual>
      <geometry>
        <mesh filename="meshes/right_wrist_yaw_link.STL" />
        </geometry>
      <material name="gray" />
      </visual>
    </link>
  <joint name="right_wrist_yaw_joint" type="fixed">
    <origin xyz="0.021 0 0" rpy="0 0 0" />
    <parent link="right_wrist_pitch_link" />
    <child link="right_wrist_yaw_link" />
    <axis xyz="0 0 1" />
    <limit lower="-1.1344" upper="1.1344" effort="25" velocity="4.44" />
    </joint>
  <link name="right_hand_link">
    <inertial>
      <origin xyz="0.07687068 0.00813452 0.00999174" rpy="0 0 0" />
      <mass value="0.41" />
      <inertia ixx="0.00046567" ixy="-6.586E-05" ixz="-0.00011179" iyy="0.00115771" iyz="0.00014438" izz="0.00101898" />
    </inertial>
    <visual>
      <geometry>
        <mesh filename="meshes/right_hand_link.STL" />
        </geometry>
      <material name="white" />
    </visual>
<!--    <collision>-->
<!--      <geometry>-->
<!--        <mesh filename="meshes/right_hand_link.STL" />-->
<!--        </geometry>-->
<!--    </collision>-->
  </link>
  <joint name="right_hand_joint" type="fixed">
    <origin xyz="0.031 0 0" rpy="0 0 0" />
    <parent link="right_wrist_yaw_link" />
    <child link="right_hand_link" />
  </joint>
  <link name="head_yaw_link">
    <inertial>
      <origin xyz="-0.01151505 -1.46912885312199E-13 0.019677" rpy="0 0 0" />
      <mass value="0.56" />
      <inertia ixx="0.0004077693" ixy="0" ixz="0.00012224" iyy="0.000458813" iyz="0" izz="0.0002944" />
    </inertial>
    <visual>
      <origin xyz="0 0 0" rpy="0 0 0" />
      <geometry>
        <mesh filename="meshes/head_yaw_link.STL" />
      </geometry>
      <material name="">
        <color rgba="0.7 0.7 0.8 1" />
      </material>
    </visual>
    <collision>
      <origin xyz="0 0 0" rpy="0 0 0" />
      <geometry>
        <mesh filename="meshes/head_yaw_link.STL" />
      </geometry>
    </collision>
  </link>
  <joint name="head_yaw_joint" type="fixed">
    <origin xyz="-0.011 0 0.5218" rpy="0 0 0" />
    <parent link="torso_link" />
    <child link="head_yaw_link" />
    <axis xyz="0 0 1" />
    <limit lower="-0.7854" upper="0.7854" effort="0" velocity="0" />
  </joint>
  <link name="head_pitch_link">
    <inertial>
      <origin xyz="0.04742965 1.03861744236181E-06 0.019240466" rpy="0 0 0" />
      <mass value="0.864" />
      <inertia ixx="0.004093924" ixy="0" ixz="0.0004171" iyy="0.004848" iyz="0" izz="0.0046611" />
    </inertial>
    <visual>
      <origin xyz="0 0 0" rpy="0 0 0" />
      <geometry>
        <mesh filename="meshes/head_pitch_link.STL" />
      </geometry>
      <material name="">
        <color rgba="0.7 0.7 0.76 1" />
      </material>
    </visual>
<!--    <collision>-->
<!--      <origin xyz="0 0 0" rpy="0 0 0" />-->
<!--      <geometry>-->
<!--        <mesh filename="meshes/head_pitch_link.STL" />-->
<!--      </geometry>-->
<!--    </collision>-->
  </link>
  <joint name="head_pitch_joint" type="fixed">
    <origin xyz="-0.0295 0 0.0503" rpy="0 0 0" />
    <parent link="head_yaw_link" />
    <child link="head_pitch_link" />
    <axis xyz="0 1 0" />
    <limit lower="-0.1745" upper="0.2618" effort="0" velocity="0" />
  </joint>

  <!-- <link name="camera"></link>
  <joint name="camera" type="fixed">
    <origin xyz="0.098272 0 0.031376" rpy="0 0.43632 0" />
    <parent link="head_pitch_link" />
    <child link="camera" />
  </joint> -->

  <link name="mid360"></link>
  <joint name="mid360" type="fixed">
    <origin xyz="-0.011002 0 0.44779" rpy="0 0 0" />
    <parent link="torso_link" />
    <child link="mid360" />
  </joint>

  <link name="imu_in_pelvis"></link>
  <joint name="imu_in_pelvis_joint" type="fixed">
    <origin xyz="0 0 -0.044" rpy="0 0 0" />
    <parent link="pelvis" />
    <child link="imu_in_pelvis" />
  </joint>
  
  </robot>
