<mujoco model="F2">
  <compiler angle="radian" meshdir="./meshes/"/>
  <default>
  <joint damping="0.1" armature="0.01" frictionloss="0.01"/>
  </default>

  <asset>
    <mesh name="pelvis" file="pelvis.STL"/>
    <mesh name="left_hip_pitch_link" file="left_hip_pitch_link.STL"/>
    <mesh name="left_hip_roll_link" file="left_hip_roll_link.STL"/>
    <mesh name="left_hip_yaw_link" file="left_hip_yaw_link.STL"/>
    <mesh name="left_knee_link" file="left_knee_link.STL"/>
    <mesh name="left_ankle_pitch_link" file="left_ankle_pitch_link.STL"/>
    <mesh name="left_ankle_roll_link" file="left_ankle_roll_link.STL"/>
    <mesh name="right_hip_pitch_link" file="right_hip_pitch_link.STL"/>
    <mesh name="right_hip_roll_link" file="right_hip_roll_link.STL"/>
    <mesh name="right_hip_yaw_link" file="right_hip_yaw_link.STL"/>
    <mesh name="right_knee_link" file="right_knee_link.STL"/>
    <mesh name="right_ankle_pitch_link" file="right_ankle_pitch_link.STL"/>
    <mesh name="right_ankle_roll_link" file="right_ankle_roll_link.STL"/>
    <mesh name="waist_yaw_link" file="waist_yaw_link.STL"/>
    <mesh name="waist_roll_link" file="waist_roll_link.STL"/>
    <mesh name="torso_link" file="torso_link.STL"/>
    <mesh name="left_shoulder_pitch_link" file="left_shoulder_pitch_link.STL"/>
    <mesh name="left_shoulder_roll_link" file="left_shoulder_roll_link.STL"/>
    <mesh name="left_shoulder_yaw_link" file="left_shoulder_yaw_link.STL"/>
    <mesh name="left_elbow_link" file="left_elbow_link.STL"/>
    <mesh name="left_wrist_roll_link" file="left_wrist_roll_link.STL"/>
    <mesh name="left_wrist_pitch_link" file="left_wrist_pitch_link.STL"/>
    <mesh name="left_wrist_yaw_link" file="left_wrist_yaw_link.STL"/>
    <mesh name="left_hand_link" file="left_hand_link.STL"/>
    <mesh name="right_shoulder_pitch_link" file="right_shoulder_pitch_link.STL"/>
    <mesh name="right_shoulder_roll_link" file="right_shoulder_roll_link.STL"/>
    <mesh name="right_shoulder_yaw_link" file="right_shoulder_yaw_link.STL"/>
    <mesh name="right_elbow_link" file="right_elbow_link.STL"/>
    <mesh name="right_wrist_roll_link" file="right_wrist_roll_link.STL"/>
    <mesh name="right_wrist_pitch_link" file="right_wrist_pitch_link.STL"/>
    <mesh name="right_wrist_yaw_link" file="right_wrist_yaw_link.STL"/>
    <mesh name="right_hand_link" file="right_hand_link.STL"/>
    <mesh name="head_yaw_link" file="head_yaw_link.STL"/>
    <mesh name="head_pitch_link" file="head_pitch_link.STL"/>
  </asset>

  <worldbody>
    <body name="pelvis" pos="0 0 0.873">
      <inertial pos="1.227e-05 0 0.00175202" quat="0.707113 0.707071 -0.00603929 0.00224665" mass="1.923" diaginertia="0.00328643 0.00327877 0.00187875"/>
      <joint name="floating_base_joint" type="free" limited="false" actuatorfrclimited="false"/>
      <geom type="mesh" contype="0" conaffinity="0" group="1" density="0" rgba="0.75294 0.75294 0.75294 1" mesh="pelvis"/>
      <geom type="sphere" name="pelvis_collision" rgba="0.75294 0.75294 0.75294 1" pos="0 0 0" size="0.06" group="3"/>
      <site name="imu_in_pelvis" size="0.01" pos="0 0 0"/>
      <body name="left_hip_pitch_link" pos="0 0.0495 0">
        <inertial pos="-0.00059823 0.053979 -0.0042224" quat="0.652315 0.75755 -0.0242065 0.00423816" mass="1.04" diaginertia="0.00138575 0.00113626 0.000872142"/>
        <joint name="left_hip_pitch_joint" pos="0 0 0" axis="0 1 0" range="-2.3562 2.3562" actuatorfrcrange="-75 75"/>
        <geom type="mesh" contype="0" conaffinity="0" group="1" density="0" rgba="0.75294 0.75294 0.75294 1" mesh="left_hip_pitch_link"/>
<!--        <geom type="mesh" rgba="0.75294 0.75294 0.75294 1" mesh="left_hip_pitch_link"/>-->
        <body name="left_hip_roll_link" pos="0 0.0555 -0.005">
          <inertial pos="0.0043213 0 -0.027634" quat="0.408553 0.57731 0.577033 0.408449" mass="0.14" diaginertia="0.00018358 0.000141244 0.000101956"/>
          <joint name="left_hip_roll_joint" pos="0 0 0" axis="1 0 0" range="-0.5236 1.5708" actuatorfrcrange="-87 87"/>
          <geom type="mesh" contype="0" conaffinity="0" group="1" density="0" rgba="0.75294 0.75294 0.75294 1" mesh="left_hip_roll_link"/>
<!--          <geom type="mesh" rgba="0.75294 0.75294 0.75294 1" mesh="left_hip_roll_link"/>-->
          <body name="left_hip_yaw_link" pos="0 0 -0.0536">
            <inertial pos="0.00010121 1.383e-05 -0.102311" quat="0.99999 0.00375205 0.0025479 0.000511966" mass="2.275" diaginertia="0.0191971 0.018658 0.00224713"/>
            <joint name="left_hip_yaw_joint" pos="0 0 0" axis="0 0 1" range="-1.8326 1.8326" actuatorfrcrange="-87 87"/>
            <geom type="mesh" contype="0" conaffinity="0" group="1" density="0" rgba="0.75294 0.75294 0.75294 1" mesh="left_hip_yaw_link"/>
<!--            <geom type="mesh" rgba="0.75294 0.75294 0.75294 1" mesh="left_hip_yaw_link"/>-->
            <body name="left_knee_link" pos="0 0 -0.3304">
              <inertial pos="0.00334882 -0.00032247 -0.149842" quat="0.698241 -0.0104039 -0.00666549 0.715757" mass="0.635" diaginertia="0.0111018 0.0110139 0.000311373"/>
              <joint name="left_knee_joint" pos="0 0 0" axis="0 1 0" range="-0.01745 2.3562" actuatorfrcrange="-120 120"/>
              <geom type="mesh" contype="0" conaffinity="0" group="1" density="0" rgba="0.75294 0.75294 0.75294 1" mesh="left_knee_link"/>
<!--              <geom type="mesh" rgba="0.75294 0.75294 0.75294 1" mesh="left_knee_link"/>-->
              <body name="left_ankle_pitch_link" pos="0 0 -0.39">
                <inertial pos="0.0024178 -1.256e-05 -0.0238176" quat="0.704903 0.052882 0.0527757 0.705358" mass="0.22" diaginertia="0.00023561 0.000170507 9.99229e-05"/>
                <joint name="left_ankle_pitch_joint" pos="0 0 0" axis="0 1 0" range="-0.873 1.0472" actuatorfrcrange="-89 89"/>
                <geom type="mesh" contype="0" conaffinity="0" group="1" density="0" rgba="0.75294 0.75294 0.75294 1" mesh="left_ankle_pitch_link"/>
<!--                <geom type="mesh" rgba="0.75294 0.75294 0.75294 1" mesh="left_ankle_pitch_link"/>-->
                <body name="left_ankle_roll_link" pos="0 0 -0.058">
                  <site name="left_foot" rgba="1 0 0 1" pos="0.04 0 -0.035"/>
                  <inertial pos="0.0510876 0.00023922 -0.00447269" quat="1 0 0 0" mass="0.411" diaginertia="0.01 0.01 0.01"/>
                  <joint name="left_ankle_roll_joint" pos="0 0 0" axis="1 0 0" range="-0.5236 0.5236" actuatorfrcrange="-12 12"/>
                  <geom type="mesh" contype="0" conaffinity="0" group="1" density="0" rgba="0.75294 0.75294 0.75294 1" mesh="left_ankle_roll_link"/>
<!--                  <geom size="0.105 0.033 0.01" pos="0.04 0 -0.013" type="box" rgba="0.75294 0.75294 0.75294 1"/>-->
                  <geom size="0.006" name="left_foot1_collision" pos="-0.066 0.034 -0.03" rgba="0.75294 0.75294 0.75294 1" group="3"/>
                  <geom size="0.006" name="left_foot2_collision" pos="-0.066 -0.034 -0.03" rgba="0.75294 0.75294 0.75294 1" group="3"/>
                  <geom size="0.006" name="left_foot3_collision" pos="0.15 0.036 -0.03" rgba="0.75294 0.75294 0.75294 1" group="3"/>
                  <geom size="0.006" name="left_foot4_collision" pos="0.15 -0.036 -0.03" rgba="0.75294 0.75294 0.75294 1" group="3"/>
                </body>
              </body>
            </body>
          </body>
        </body>
      </body>
      <body name="right_hip_pitch_link" pos="0 -0.0495 0">
        <inertial pos="-0.00059823 -0.053979 -0.0042224" quat="0.75755 0.652315 -0.00423816 0.0242065" mass="1.04" diaginertia="0.00138575 0.00113626 0.000872142"/>
        <joint name="right_hip_pitch_joint" pos="0 0 0" axis="0 1 0" range="-2.3562 2.3562" actuatorfrcrange="-75 75"/>
        <geom type="mesh" contype="0" conaffinity="0" group="1" density="0" rgba="0.75294 0.75294 0.75294 1" mesh="right_hip_pitch_link"/>
<!--        <geom type="mesh" rgba="0.75294 0.75294 0.75294 1" mesh="right_hip_pitch_link"/>-->
        <body name="right_hip_roll_link" pos="0 -0.0555 -0.005">
          <inertial pos="0.0043213 0 -0.027634" quat="0.408553 0.57731 0.577033 0.408449" mass="0.14" diaginertia="0.00018358 0.000141244 0.000101956"/>
          <joint name="right_hip_roll_joint" pos="0 0 0" axis="1 0 0" range="-1.5708 0.5236" actuatorfrcrange="-87 87"/>
          <geom type="mesh" contype="0" conaffinity="0" group="1" density="0" rgba="0.75294 0.75294 0.75294 1" mesh="right_hip_roll_link"/>
<!--          <geom type="mesh" rgba="0.75294 0.75294 0.75294 1" mesh="right_hip_roll_link"/>-->
          <body name="right_hip_yaw_link" pos="0 0 -0.0536">
            <inertial pos="0.00028095 -0.00037298 -0.102311" quat="0.999997 0.00155532 0.00134116 0.00120674" mass="2.275" diaginertia="0.0191961 0.0186572 0.00224772"/>
            <joint name="right_hip_yaw_joint" pos="0 0 0" axis="0 0 1" range="-1.8326 1.8326" actuatorfrcrange="-87 87"/>
            <geom type="mesh" contype="0" conaffinity="0" group="1" density="0" rgba="0.75294 0.75294 0.75294 1" mesh="right_hip_yaw_link"/>
<!--            <geom type="mesh" rgba="0.75294 0.75294 0.75294 1" mesh="right_hip_yaw_link"/>-->
            <body name="right_knee_link" pos="0 0 -0.3304">
              <inertial pos="0.0033489 -0.00032248 -0.14984" quat="0.715839 -0.00666391 -0.0104045 0.698156" mass="0.635" diaginertia="0.0111013 0.0110142 0.000311373"/>
              <joint name="right_knee_joint" pos="0 0 0" axis="0 1 0" range="-0.01745 2.3562" actuatorfrcrange="-120 120"/>
              <geom type="mesh" contype="0" conaffinity="0" group="1" density="0" rgba="0.75294 0.75294 0.75294 1" mesh="right_knee_link"/>
<!--              <geom type="mesh" rgba="0.75294 0.75294 0.75294 1" mesh="right_knee_link"/>-->
              <body name="right_ankle_pitch_link" pos="0 0 -0.39">
                <inertial pos="0.0024178 -1.257e-05 -0.023818" quat="0.704903 0.052882 0.0527757 0.705358" mass="0.22" diaginertia="0.00023561 0.000170507 9.99229e-05"/>
                <joint name="right_ankle_pitch_joint" pos="0 0 0" axis="0 1 0" range="-0.873 1.0472" actuatorfrcrange="-89 89"/>
                <geom type="mesh" contype="0" conaffinity="0" group="1" density="0" rgba="0.75294 0.75294 0.75294 1" mesh="right_ankle_pitch_link"/>
<!--                <geom type="mesh" rgba="0.75294 0.75294 0.75294 1" mesh="right_ankle_pitch_link"/>-->
                <body name="right_ankle_roll_link" pos="0 0 -0.058">
                  <site name="right_foot" rgba="1 0 0 1" pos="0.04 0 -0.035"/>
                  <inertial pos="0.0490176 4.088e-05 -0.00448631" quat="1 0 0 0" mass="0.411" diaginertia="0.01 0.01 0.01"/>
                  <joint name="right_ankle_roll_joint" pos="0 0 0" axis="1 0 0" range="-0.5236 0.5236" actuatorfrcrange="-12 12"/>
                  <geom type="mesh" contype="0" conaffinity="0" group="1" density="0" rgba="0.75294 0.75294 0.75294 1" mesh="right_ankle_roll_link"/>
<!--                  <geom size="0.105 0.033 0.01" pos="0.04 0 -0.013" type="box" rgba="0.75294 0.75294 0.75294 1"/>-->
                  <geom size="0.006" name="right_foot1_collision" pos="-0.066 0.034 -0.03" rgba="0.75294 0.75294 0.75294 1" group="3"/>
                  <geom size="0.006" name="right_foot2_collision" pos="-0.066 -0.034 -0.03" rgba="0.75294 0.75294 0.75294 1" group="3"/>
                  <geom size="0.006" name="right_foot3_collision" pos="0.15 0.036 -0.03" rgba="0.75294 0.75294 0.75294 1" group="3"/>
                  <geom size="0.006" name="right_foot4_collision" pos="0.15 -0.036 -0.03" rgba="0.75294 0.75294 0.75294 1" group="3"/>
                </body>
              </body>
            </body>
          </body>
        </body>
      </body>
      <body name="waist_yaw_link" pos="0 0 0.0955">
        <inertial pos="-0.000168719 0 0.00494718" quat="0.705214 0.0517024 0.0517024 0.705214" mass="0.274" diaginertia="0.000141864 0.000115748 0.00010802"/>
        <joint name="waist_yaw_joint" pos="0 0 0" axis="0 0 1" range="-1.5708 1.5708" actuatorfrcrange="-87 87"/>
        <geom type="mesh" contype="0" conaffinity="0" group="1" density="0" rgba="1 1 1 1" mesh="waist_yaw_link"/>
        <geom type="mesh" contype="0" conaffinity="0" group="1" density="0" rgba="1 1 1 1" mesh="waist_roll_link"/>
        <body name="torso_link">
          <inertial pos="0.0294011 0.000755467 0.198523" quat="0.968186 -0.00506918 -0.25018 0.000512508" mass="17.267" diaginertia="0.469654 0.357006 0.340049"/>
          <joint name="waist_roll_joint" pos="0 0 0" axis="1 0 0" range="-0.5236 0.5236" actuatorfrcrange="-87 87"/>
          <geom type="mesh" contype="0" conaffinity="0" group="1" density="0" rgba="0.5 0 0 1" mesh="torso_link"/>
          <site name="imu_in_torso" size="0.01" pos="0 0 0.03"/>
          <geom pos="-0.015 0.05635 0.342" quat="1 0 0 0" type="mesh" contype="0" conaffinity="0" group="1" density="0" rgba="0.75294 0.75294 0.75294 1" mesh="left_shoulder_pitch_link"/>
          <geom pos="-0.015 0.15945 0.342" type="mesh" contype="0" conaffinity="0" group="1" density="0" rgba="0.75294 0.75294 0.75294 1" mesh="left_shoulder_roll_link"/>
          <geom pos="-0.015 0.15945 0.342" type="mesh" contype="0" conaffinity="0" group="1" density="0" rgba="0.75294 0.75294 0.75294 1" mesh="left_shoulder_yaw_link"/>
          <geom pos="-0.015 0.15945 0.1125" quat="1 0 0 0" type="mesh" contype="0" conaffinity="0" group="1" density="0" rgba="0.75294 0.75294 0.75294 1" mesh="left_elbow_link"/>
          <geom pos="-0.015 0.15945 0.1125" quat="1 0 0 0" type="mesh" contype="0" conaffinity="0" group="1" density="0" rgba="0.75294 0.75294 0.75294 1" mesh="left_wrist_roll_link"/>
          <geom pos="0.215 0.15945 0.1125" quat="1 0 0 0" type="mesh" contype="0" conaffinity="0" group="1" density="0" rgba="0.75294 0.75294 0.75294 1" mesh="left_wrist_pitch_link"/>
          <geom pos="0.236 0.15945 0.1125" quat="1 0 0 0" type="mesh" contype="0" conaffinity="0" group="1" density="0" rgba="0.75294 0.75294 0.75294 1" mesh="left_wrist_yaw_link"/>
          <geom pos="0.267 0.15945 0.1125" quat="1 0 0 0" type="mesh" contype="0" conaffinity="0" group="1" density="0" rgba="1 1 1 1" mesh="left_hand_link"/>
          <geom pos="-0.015 -0.05635 0.342" quat="1 0 0 0" type="mesh" contype="0" conaffinity="0" group="1" density="0" rgba="0.75294 0.75294 0.75294 1" mesh="right_shoulder_pitch_link"/>
          <geom pos="-0.015 -0.15945 0.342" type="mesh" contype="0" conaffinity="0" group="1" density="0" rgba="0.75294 0.75294 0.75294 1" mesh="right_shoulder_roll_link"/>
          <geom pos="-0.015 -0.15945 0.342" type="mesh" contype="0" conaffinity="0" group="1" density="0" rgba="0.75294 0.75294 0.75294 1" mesh="right_shoulder_yaw_link"/>
          <geom pos="-0.015 -0.15945 0.1125" quat="1 0 0 0" type="mesh" contype="0" conaffinity="0" group="1" density="0" rgba="0.75294 0.75294 0.75294 1" mesh="right_elbow_link"/>
          <geom pos="-0.015 -0.15945 0.1125" quat="1 0 0 0" type="mesh" contype="0" conaffinity="0" group="1" density="0" rgba="0.75294 0.75294 0.75294 1" mesh="right_wrist_roll_link"/>
          <geom pos="0.215 -0.15945 0.1125" quat="1 0 0 0" type="mesh" contype="0" conaffinity="0" group="1" density="0" rgba="0.75294 0.75294 0.75294 1" mesh="right_wrist_pitch_link"/>
          <geom pos="0.236 -0.15945 0.1125" quat="1 0 0 0" type="mesh" contype="0" conaffinity="0" group="1" density="0" rgba="0.75294 0.75294 0.75294 1" mesh="right_wrist_yaw_link"/>
          <geom pos="0.267 -0.15945 0.1125" quat="1 0 0 0" type="mesh" contype="0" conaffinity="0" group="1" density="0" rgba="1 1 1 1" mesh="right_hand_link"/>
          <geom pos="-0.011 0 0.5218" type="mesh" contype="0" conaffinity="0" group="1" density="0" rgba="0.7 0.7 0.8 1" mesh="head_yaw_link"/>
          <geom name="head_collision" pos="-0.011 0 0.5218" type="sphere" rgba="0.7 0.7 0.8 1" size="0.04" group="3"/>
          <geom pos="-0.0405 0 0.5721" quat="1 0 0 0" type="mesh" contype="0" conaffinity="0" group="1" density="0" rgba="0.7 0.7 0.76 1" mesh="head_pitch_link"/>
        </body>
      </body>
    </body>
  </worldbody>
<!--  <actuator>-->
<!--    <motor name="left_hip_pitch_joint" joint="left_hip_pitch_joint"/>-->
<!--    <motor name="left_hip_roll_joint" joint="left_hip_roll_joint"/>-->
<!--    <motor name="left_hip_yaw_joint" joint="left_hip_yaw_joint"/>-->
<!--    <motor name="left_knee_joint" joint="left_knee_joint"/>-->
<!--    <motor name="left_ankle_pitch_joint" joint="left_ankle_pitch_joint"/>-->
<!--    <motor name="left_ankle_roll_joint" joint="left_ankle_roll_joint"/>-->

<!--    <motor name="right_hip_pitch_joint" joint="right_hip_pitch_joint"/>-->
<!--    <motor name="right_hip_roll_joint" joint="right_hip_roll_joint"/>-->
<!--    <motor name="right_hip_yaw_joint" joint="right_hip_yaw_joint"/>-->
<!--    <motor name="right_knee_joint" joint="right_knee_joint"/>-->
<!--    <motor name="right_ankle_pitch_joint" joint="right_ankle_pitch_joint"/>-->
<!--    <motor name="right_ankle_roll_joint" joint="right_ankle_roll_joint"/>-->

<!--    <motor name="waist_yaw_joint" joint="waist_yaw_joint"/>-->
<!--    <motor name="waist_roll_joint" joint="waist_roll_joint"/>-->
<!--  </actuator>-->
  <visual>
    <headlight diffuse="0.6 0.6 0.6" ambient="0.1 0.1 0.1" specular="0.9 0.9 0.9"/>
    <rgba haze="0.15 0.25 0.35 1"/>
    <global azimuth="-140" elevation="-20"/>
  </visual>

  <asset>
    <texture type="skybox" builtin="gradient" rgb1="0 0 0" rgb2="0 0 0" width="800" height="800"/>
    <texture type="2d" name="plane" builtin="checker" mark="edge" rgb1="0.3 0.4 0.5" rgb2="0.1 0.2 0.3" markrgb="0.8 0.8 0.8" width="300" height="300"/>
    <material name="plane" texture="plane" texuniform="true" texrepeat="2 2" reflectance="0.0"/>
  </asset>

<!--  <worldbody>-->
<!--    <light mode="trackcom" pos="1 0 3.5" dir="0 0 -1" directional="true"/>-->
<!--    <geom name="floor" size="0 0 0.05" type="plane" material="plane" friction="1.0" />-->
<!--  </worldbody>-->

    <sensor>
    <gyro name="imu_ang_vel" site="imu_in_pelvis"/>
    <velocimeter name="imu_lin_vel" site="imu_in_pelvis"/>
    <accelerometer name="imu_lin_acc" site="imu_in_pelvis"/>
    <framezaxis name="imu_upvector" objtype="body" objname="world" reftype="site" refname="imu_in_pelvis"/>
    <subtreeangmom name="root_angmom" body="pelvis"/>
  </sensor>

</mujoco>
